<?xml version="1.0"?>
<robot xmlns:xacro="http://ros.org/wiki/xacro">

  <xacro:include filename="$(find echo_bot_description)/urdf/leg/echo_bot_leg.transmission.xacro"/>

  <xacro:macro name="leg_v0" params="parent prefix *joint_origin">
    <!-- Link -->
    <link name="upper_${prefix}leg_link">
      <visual>
        <origin xyz="0 0 0" rpy="0 0 0"/>
        <geometry>
          <mesh filename="package://echo_bot_description/meshes/DAE/upper_leg.dae"/>
        </geometry>
      </visual>
      <collision>
        <origin xyz="0 0 0" rpy="0 0 0"/>
        <geometry>
          <mesh filename="package://echo_bot_description/meshes/STL/upper_leg.stl"/>
        </geometry>      
      </collision>
      <inertial>
        <inertia  ixx="0.000311"
                  ixy="0.0"
                  ixz="0.000001" 
                  iyy="0.000394" 
                  iyz="0.0" 
                  izz="0.000622" />
        <mass value="0.5"/>
        <origin xyz="0.045 0 -0.001" rpy="0 0 0"/>
      </inertial>
    </link>
    <link name="lower_${prefix}leg_link">
      <visual>
        <origin xyz="0 0 0" rpy="0 0 0"/>
        <geometry>
          <mesh filename="package://echo_bot_description/meshes/DAE/lower_${prefix}leg.dae"/>
        </geometry>
      </visual>
      <collision>
        <origin xyz="0 0 0" rpy="0 0 0"/>
        <geometry>
          <mesh filename="package://echo_bot_description/meshes/STL/lower_${prefix}leg.stl"/>
        </geometry>      
      </collision>
      <inertial>
        <inertia  ixx="0.000151"
                  ixy="-0.000041"
                  ixz="-0.000004" 
                  iyy="0.000795" 
                  iyz="0.0" 
                  izz="0.000777" />
        <mass value="0.5"/>
        <origin xyz="0.058 0.001 -0.001" rpy="0 0 0"/>
      </inertial>
    </link>
    <link name="upper_side_${prefix}leg_link">
      <visual>
        <origin xyz="0 0 0" rpy="0 0 0"/>
        <material name="leg_color_0"/>
        <geometry>
          <mesh filename="package://echo_bot_description/meshes/DAE/upper_side_leg.dae"/>
        </geometry>
      </visual>
      <collision>
        <origin xyz="0 0 0" rpy="0 0 0"/>
        <geometry>
          <mesh filename="package://echo_bot_description/meshes/STL/upper_side_leg.stl"/>
        </geometry>      
      </collision>
      <inertial>
        <inertia  ixx="0.000018"
                  ixy="0.0"
                  ixz="0.0" 
                  iyy="0.000316"
                  iyz="0.0"
                  izz="0.000314"/>
        <mass value="0.5"/>
        <origin xyz="0.05 0 0" rpy="0 0 0"/>
      </inertial>
    </link>

    <!-- Joint -->
    <joint name="torso_to_upper_${prefix}leg" type="revolute">
      <insert_block name="joint_origin"/>
      <parent link="${parent}" />
      <child link="upper_${prefix}leg_link" />
      <axis xyz="0 1 0"/>
      <limit lower="0.0" upper="0.52359879" effort="100" velocity="${M_PI}"/>
      <dynamics damping="0.1"/>
    </joint>
    <xacro:leg_effort_trans_v0 joint="torso_to_upper_${prefix}leg"/>

    <joint name="upper_${prefix}leg_to_lower_${prefix}leg" type="continuous">
      <origin xyz="0.1 0.0 0.0" rpy="0.0 -1.36 0.0" />
      <parent link="upper_${prefix}leg_link" />
      <child link="lower_${prefix}leg_link" />
      <axis xyz="0 1 0"/>
      <!-- <mimic joint="upper_${prefix}leg_link_joint" multiplier="-2.186" offset="-0.02025"/> -->
    </joint>

    <joint name="lower_${prefix}leg_to_upper_side_${prefix}leg" type="continuous">
      <origin xyz="-0.025 0.0 0.0" rpy="0.0 -2.08 0.0" />
      <parent link="lower_${prefix}leg_link" />
      <child link="upper_side_${prefix}leg_link" />
      <axis xyz="0 1 0"/>
      <!-- <mimic joint="upper_${prefix}leg_link_joint" multiplier="2.123937" offset="0.003625"/> -->
    </joint>

  </xacro:macro>
</robot>