<?xml version="1.0" encoding="utf-8"?>
<!-- =================================================================================== -->
<!-- |    This document was autogenerated by xacro from echo_bot.urdf.xacro            | -->
<!-- |    EDITING THIS FILE BY HAND IS NOT RECOMMENDED                                 | -->
<!-- =================================================================================== -->
<robot name="echo_bot">
  <!-- == echo_bot base == -->
  <link name="base_link"/>
  <link name="torso_link">
    <visual>
      <origin rpy="0 0 0" xyz="0 0 0"/>
      <geometry>
        <mesh filename="package://echo_bot_description/meshes/DAE/torso.dae"/>
      </geometry>
    </visual>
    <collision>
      <origin rpy="0 0 0" xyz="0 0 0"/>
      <geometry>
        <mesh filename="package://echo_bot_description/meshes/STL/torso.stl"/>
      </geometry>
    </collision>
    <inertial>
      <inertia ixx="0.006594" ixy="0.0" ixz="0.000999" iyy="0.007405" iyz="0.0" izz="0.010608"/>
      <mass value="2.915"/>
      <origin rpy="0 0 0" xyz="0.025 0 0.053"/>
    </inertial>
  </link>
  <link name="torso_back_left"/>
  <!-- <link name="torso_back_right"/> -->
  <joint name="torso_link_to_torso_back_left" type="fixed">
    <origin xyz="-0.04 0.0475 0.035"/>
    <parent link="torso_link"/>
    <child link="torso_back_left"/>
  </joint>
  <!-- <joint name="torso_link_to_torso_back_right" type="fixed">
      <origin xyz="-0.04 -0.0475 0.035"/>
      <parent link="torso_link"/>
      <child link="torso_back_right"/>
    </joint> -->
  <joint name="base_link_to_torso_link" type="fixed">
    <origin rpy="0 0 0" xyz="0 0 0"/>
    <parent link="base_link"/>
    <child link="torso_link"/>
  </joint>
  <!-- <link name="base_footprint"/>
  <joint name="base_link_to_base_footprint_joint" type="fixed">
    <origin xyz="0 0 0.090"/>
    <parent link="base_link"/>
    <child link="base_footprint"/>
  </joint> -->
  <!-- Link -->
  <link name="upper_lleg_link">
    <visual>
      <origin rpy="0 0 0" xyz="0 0 0"/>
      <geometry>
        <mesh filename="package://echo_bot_description/meshes/DAE/upper_leg.dae"/>
      </geometry>
    </visual>
    <collision>
      <origin rpy="0 0 0" xyz="0 0 0"/>
      <geometry>
        <mesh filename="package://echo_bot_description/meshes/STL/upper_leg.stl"/>
      </geometry>
    </collision>
    <inertial>
      <inertia ixx="0.000311" ixy="0.0" ixz="0.000001" iyy="0.000394" iyz="0.0" izz="0.000622"/>
      <mass value="0.5"/>
      <origin rpy="0 0 0" xyz="0.045 0 -0.001"/>
    </inertial>
  </link>
  <link name="lower_lleg_link">
    <visual>
      <origin rpy="0 0 0" xyz="0 0 0"/>
      <geometry>
        <mesh filename="package://echo_bot_description/meshes/DAE/lower_lleg.dae"/>
      </geometry>
    </visual>
    <collision>
      <origin rpy="0 0 0" xyz="0 0 0"/>
      <geometry>
        <mesh filename="package://echo_bot_description/meshes/STL/lower_lleg.stl"/>
      </geometry>
    </collision>
    <inertial>
      <inertia ixx="0.000151" ixy="-0.000041" ixz="-0.000004" iyy="0.000795" iyz="0.0" izz="0.000777"/>
      <mass value="0.5"/>
      <origin rpy="0 0 0" xyz="0.058 0.001 -0.001"/>
    </inertial>
  </link>
  <link name="upper_side_lleg_link">
    <visual>
      <origin rpy="0 0 0" xyz="0 0 0"/>
      <material name="leg_color_0"/>
      <geometry>
        <mesh filename="package://echo_bot_description/meshes/DAE/upper_side_leg.dae"/>
      </geometry>
    </visual>
    <collision>
      <origin rpy="0 0 0" xyz="0 0 0"/>
      <geometry>
        <mesh filename="package://echo_bot_description/meshes/STL/upper_side_leg.stl"/>
      </geometry>
    </collision>
    <inertial>
      <inertia ixx="0.000018" ixy="0.0" ixz="0.0" iyy="0.000316" iyz="0.0" izz="0.000314"/>
      <mass value="0.5"/>
      <origin rpy="0 0 0" xyz="0.05 0 0"/>
    </inertial>
  </link>
  <!-- Joint -->
  <joint name="torso_to_upper_lleg" type="revolute">
    <origin rpy="0.0 2.27 0.0" xyz="0.0 0.0475 0.0"/>
    <parent link="torso_link"/>
    <child link="upper_lleg_link"/>
    <axis xyz="0 1 0"/>
    <limit effort="100" lower="0.0" upper="0.52359879" velocity="3.14159274"/>
    <dynamics damping="0.1"/>
  </joint>
  <transmission name="torso_to_upper_lleg_trans">
    <type>transmission_interface/SimpleTransmission</type>
    <joint name="torso_to_upper_lleg">
      <hardwareInterface>hardware_interface/EffortJointInterface</hardwareInterface>
    </joint>
    <actuator name="torso_to_upper_lleg_motor">
      <hardwareInterface>hardware_interface/EffortJointInterface</hardwareInterface>
      <mechanicalReduction>1</mechanicalReduction>
    </actuator>
  </transmission>
  <joint name="upper_lleg_to_lower_lleg" type="continuous">
    <origin rpy="0.0 -1.36 0.0" xyz="0.1 0.0 0.0"/>
    <parent link="upper_lleg_link"/>
    <child link="lower_lleg_link"/>
    <axis xyz="0 1 0"/>
    <!-- <mimic joint="upper_${prefix}leg_link_joint" multiplier="-2.186" offset="-0.02025"/> -->
  </joint>
  <joint name="lower_lleg_to_upper_side_lleg" type="continuous">
    <origin rpy="0.0 -2.08 0.0" xyz="-0.025 0.0 0.0"/>
    <parent link="lower_lleg_link"/>
    <child link="upper_side_lleg_link"/>
    <axis xyz="0 1 0"/>
    <!-- <mimic joint="upper_${prefix}leg_link_joint" multiplier="2.123937" offset="0.003625"/> -->
  </joint>
  <!-- Link -->
  <link name="upper_rleg_link">
    <visual>
      <origin rpy="0 0 0" xyz="0 0 0"/>
      <geometry>
        <mesh filename="package://echo_bot_description/meshes/DAE/upper_leg.dae"/>
      </geometry>
    </visual>
    <collision>
      <origin rpy="0 0 0" xyz="0 0 0"/>
      <geometry>
        <mesh filename="package://echo_bot_description/meshes/STL/upper_leg.stl"/>
      </geometry>
    </collision>
    <inertial>
      <inertia ixx="0.000311" ixy="0.0" ixz="0.000001" iyy="0.000394" iyz="0.0" izz="0.000622"/>
      <mass value="0.5"/>
      <origin rpy="0 0 0" xyz="0.045 0 -0.001"/>
    </inertial>
  </link>
  <link name="lower_rleg_link">
    <visual>
      <origin rpy="0 0 0" xyz="0 0 0"/>
      <geometry>
        <mesh filename="package://echo_bot_description/meshes/DAE/lower_rleg.dae"/>
      </geometry>
    </visual>
    <collision>
      <origin rpy="0 0 0" xyz="0 0 0"/>
      <geometry>
        <mesh filename="package://echo_bot_description/meshes/STL/lower_rleg.stl"/>
      </geometry>
    </collision>
    <inertial>
      <inertia ixx="0.000151" ixy="-0.000041" ixz="-0.000004" iyy="0.000795" iyz="0.0" izz="0.000777"/>
      <mass value="0.5"/>
      <origin rpy="0 0 0" xyz="0.058 0.001 -0.001"/>
    </inertial>
  </link>
  <link name="upper_side_rleg_link">
    <visual>
      <origin rpy="0 0 0" xyz="0 0 0"/>
      <material name="leg_color_0"/>
      <geometry>
        <mesh filename="package://echo_bot_description/meshes/DAE/upper_side_leg.dae"/>
      </geometry>
    </visual>
    <collision>
      <origin rpy="0 0 0" xyz="0 0 0"/>
      <geometry>
        <mesh filename="package://echo_bot_description/meshes/STL/upper_side_leg.stl"/>
      </geometry>
    </collision>
    <inertial>
      <inertia ixx="0.000018" ixy="0.0" ixz="0.0" iyy="0.000316" iyz="0.0" izz="0.000314"/>
      <mass value="0.5"/>
      <origin rpy="0 0 0" xyz="0.05 0 0"/>
    </inertial>
  </link>
  <!-- Joint -->
  <joint name="torso_to_upper_rleg" type="revolute">
    <origin rpy="0.0 2.27 0.0" xyz="0.0 -0.0475 0.0"/>
    <parent link="torso_link"/>
    <child link="upper_rleg_link"/>
    <axis xyz="0 1 0"/>
    <limit effort="100" lower="0.0" upper="0.52359879" velocity="3.14159274"/>
    <dynamics damping="0.1"/>
  </joint>
  <transmission name="torso_to_upper_rleg_trans">
    <type>transmission_interface/SimpleTransmission</type>
    <joint name="torso_to_upper_rleg">
      <hardwareInterface>hardware_interface/EffortJointInterface</hardwareInterface>
    </joint>
    <actuator name="torso_to_upper_rleg_motor">
      <hardwareInterface>hardware_interface/EffortJointInterface</hardwareInterface>
      <mechanicalReduction>1</mechanicalReduction>
    </actuator>
  </transmission>
  <joint name="upper_rleg_to_lower_rleg" type="continuous">
    <origin rpy="0.0 -1.36 0.0" xyz="0.1 0.0 0.0"/>
    <parent link="upper_rleg_link"/>
    <child link="lower_rleg_link"/>
    <axis xyz="0 1 0"/>
    <!-- <mimic joint="upper_${prefix}leg_link_joint" multiplier="-2.186" offset="-0.02025"/> -->
  </joint>
  <joint name="lower_rleg_to_upper_side_rleg" type="continuous">
    <origin rpy="0.0 -2.08 0.0" xyz="-0.025 0.0 0.0"/>
    <parent link="lower_rleg_link"/>
    <child link="upper_side_rleg_link"/>
    <axis xyz="0 1 0"/>
    <!-- <mimic joint="upper_${prefix}leg_link_joint" multiplier="2.123937" offset="0.003625"/> -->
  </joint>
  <link name="wheel_l">
    <visual>
      <geometry>
        <mesh filename="package://echo_bot_description/meshes/DAE/tyre.dae"/>
      </geometry>
    </visual>
    <collision>
      <!-- <origin xyz="0 -0.003 0" rpy="${-M_PI/2} 0 0"/> -->
      <origin rpy="0 0 0" xyz="0 0 0"/>
      <geometry>
        <!-- <cylinder radius="${wheel_radius}" length="${wheel_length}"/> -->
        <mesh filename="package://echo_bot_description/meshes/STL/tyre.stl"/>
      </geometry>
    </collision>
    <inertial>
      <origin rpy="0 0 0" xyz="0.0 0.0 0.0"/>
      <mass value="0.039831"/>
      <inertia ixx="8.85243975e-06" ixy="0.0" ixz="0.0" iyy="8.85243975e-06" iyz="0.0" izz="1.67489355e-05"/>
      <!-- <cylinder_inertial  mass="${wheel_mass}"
                            radius="${wheel_radius}" length="${wheel_length}"/> -->
    </inertial>
  </link>
  <joint name="lower_lleg_to_wheel_l" type="continuous">
    <origin rpy="-1.57079637 0.0 0.0" xyz="0.1 0.0305 0.0"/>
    <parent link="lower_lleg_link"/>
    <child link="wheel_l"/>
    <axis xyz="0 0 1"/>
    <limit effort="0.4" velocity="12.0"/>
  </joint>
  <transmission name="lower_lleg_to_wheel_l_trans">
    <type>transmission_interface/SimpleTransmission</type>
    <joint name="lower_lleg_to_wheel_l">
      <hardwareInterface>hardware_interface/VelocityJointInterface</hardwareInterface>
    </joint>
    <actuator name="lower_lleg_to_wheel_l_motor">
      <hardwareInterface>hardware_interface/VelocityJointInterface</hardwareInterface>
      <mechanicalReduction>1</mechanicalReduction>
    </actuator>
  </transmission>
  <link name="wheel_r">
    <visual>
      <geometry>
        <mesh filename="package://echo_bot_description/meshes/DAE/tyre.dae"/>
      </geometry>
    </visual>
    <collision>
      <!-- <origin xyz="0 -0.003 0" rpy="${-M_PI/2} 0 0"/> -->
      <origin rpy="0 0 0" xyz="0 0 0"/>
      <geometry>
        <!-- <cylinder radius="${wheel_radius}" length="${wheel_length}"/> -->
        <mesh filename="package://echo_bot_description/meshes/STL/tyre.stl"/>
      </geometry>
    </collision>
    <inertial>
      <origin rpy="0 0 0" xyz="0.0 0.0 0.0"/>
      <mass value="0.039831"/>
      <inertia ixx="8.85243975e-06" ixy="0.0" ixz="0.0" iyy="8.85243975e-06" iyz="0.0" izz="1.67489355e-05"/>
      <!-- <cylinder_inertial  mass="${wheel_mass}"
                            radius="${wheel_radius}" length="${wheel_length}"/> -->
    </inertial>
  </link>
  <joint name="lower_rleg_to_wheel_r" type="continuous">
    <origin rpy="-1.57079637 0.0 0.0" xyz="0.1 -0.0305 0.0"/>
    <parent link="lower_rleg_link"/>
    <child link="wheel_r"/>
    <axis xyz="0 0 1"/>
    <limit effort="0.4" velocity="12.0"/>
  </joint>
  <transmission name="lower_rleg_to_wheel_r_trans">
    <type>transmission_interface/SimpleTransmission</type>
    <joint name="lower_rleg_to_wheel_r">
      <hardwareInterface>hardware_interface/VelocityJointInterface</hardwareInterface>
    </joint>
    <actuator name="lower_rleg_to_wheel_r_motor">
      <hardwareInterface>hardware_interface/VelocityJointInterface</hardwareInterface>
      <mechanicalReduction>1</mechanicalReduction>
    </actuator>
  </transmission>
  <link name="lidar_link">
    <visual>
      <origin rpy="0 0 0" xyz="0 0 0"/>
      <geometry>
        <cylinder length="0.02" radius="0.01"/>
      </geometry>
    </visual>
    <collision>
      <origin rpy="0 0 0" xyz="0 0 0"/>
      <geometry>
        <cylinder length="0.02" radius="0.01"/>
      </geometry>
    </collision>
    <inertial>
      <inertia ixx="2.1733e-6" ixy="0.0" ixz="0.0" iyy="2.1733e-6" iyz="0.0" izz="1.8e-7"/>
      <mass value="0.01"/>
      <origin rpy="0 0 0" xyz="0 0 0"/>
    </inertial>
  </link>
  <joint name="lidar_joint" type="fixed">
    <origin rpy="0 0 0" xyz="0 0 0.11"/>
    <parent link="torso_link"/>
    <child link="lidar_link"/>
  </joint>
  <link name="imu_link">
    <visual>
      <origin rpy="0 0 0" xyz="0 0 0"/>
      <geometry>
        <cylinder length="0.02" radius="0.01"/>
      </geometry>
    </visual>
    <collision>
      <origin rpy="0 0 0" xyz="0 0 0"/>
      <geometry>
        <cylinder length="0.02" radius="0.01"/>
      </geometry>
    </collision>
    <inertial>
      <inertia ixx="2.1733e-6" ixy="0.0" ixz="0.0" iyy="2.1733e-6" iyz="0.0" izz="1.8e-7"/>
      <mass value="0.01"/>
      <origin rpy="0 0 0" xyz="0 0 0"/>
    </inertial>
  </link>
  <joint name="imu_joint" type="fixed">
    <origin rpy="0 0 0" xyz="0 0 0"/>
    <parent link="torso_link"/>
    <child link="imu_link"/>
  </joint>
</robot>

